Workbook

Sheet TABLAS 
B1: Instrucciones | C1: 1.- En esta sección se pueden renombrar las tablas considerando las buenas prácticas y nomenclatura sugeridas. Nota: Utilización obligatoria de snake_case, no debe colocar nombres muy largos o muy cortos. 2.- Presentar (como tablas) las entidades resultantes del Modelo Relacional 3.- Presentar (como tablas) las relaciones resultantes del Modelo Relacional. Nota: Recuerde que solamente debe colocar las relaciones NO DESCARTADAS 4.- Colocar en la columna "Orígen" si la tabla es derivada de una Entidad o una Relación 5.- En las observaciones podría informar sobre claves primarias y foráneas.
A2: ENTIDADES
A3: # | B3: Tabla | C3: Descripción Tabla | D3: Origen Entidad o Relación | E3: Observaciones
A4: 1 | B4: usuario | C4: Se refiere a los usuarios del sistema de información de la Red Pascualina. Un usuario debe tener asociado un tipo de usuario. NOTA IMPORTANTE: además de tener un tipo de usuario, debe tener un rol dentro de la Red. | D4: Entidad | E4: PK = id_usuario; FK = id_tipo_usuario, id_rol;
A5: =A4+1 -> 2 | B5: rol | C5: Los roles pueden ser los siguientes: administrador (adminstra la configuración de la Red en el BackOficce), auxiliar que apoya ciertas operaciones en el BacOffice, miembro (ingresa a la Red y participa en todas las actividades inherentes a este) y visitante (usuarios especiales bajo evaluación que frecuentan la Red Social. Los ingresa el usuario Administrador | D5: Entidad | E5: PK = id_rol
A6: =A5+1 -> 3 | B6: tipo_usuario | C6: Estos son potenciales tipos de usuario: estudiante, docente, empleado, empresario, invitado, público en general, entre otros. Sirve para clasificación y estadística. Los ingresa el Usuario con Rol de Administrador. | D6: Entidad | E6: PK = id_tipo_usuario
A7: =A6+1 -> 4 | B7: perfil | C7: Compartir su área de estudio, intereses, habilidades en diferentes disciplinas o deportes, etc. Estos perfiles permiten conectar con compañeros para encontrar y seguir a otros estudiantes con intereses y/o actividades similares. | D7: Entidad | E7: PK = id_perfil
A8: =A7+1 -> 5 | B8: publicacion | C8: Compartir preguntas sobre tareas, recursos útiles, noticias de la industria tecnológica o incluso memes relevantes para la vida universitaria, entre otros. Las ingresa el usuario participante. | D8: Entidad | E8: PK = id_publicacion; FK = id_usuario
A9: =A8+1 -> 6 | B9: comentario | C9: Comentarios que se hacen a las publicaciones. Ejemplo: un estudiante publica una nota sobre la participación de Colombia en el Mundial de Fútbol; otros usuarios pueden comentar esta publicación | D9: Entidad | E9: PK = id_comentario; FK = id_usuario, id_publicacion
A10: =A9+1 -> 7 | B10: grupo | C10: Los grupos pueden ser de estudio para materias específicas, equipos para hackatones o clubes de interés (videojuegos, programación competitiva, etc.). También los empleados pueden tener sus grupos así como los docentes y los empresarios. Un grupo debe tener asociado un “Perfil”. Los ingresa el usuario participante. | D10: Entidad | E10: PK = id_grupo; FK = id_perfil
A11: =8 -> 8 | B11: servicio | C11: Los servicios los ofrece un usuario. Debe tener asociado un “Tipo de Servicio” con su descripción y precio (duración y ubicación si aplica). Los ingresa el usuario participante. | D11: Entidad | E11: PK = id_servicio; FK = id_usuario, id_tipo_servicio
A12: =9 -> 9 | B12: tipo_servicio | C12: Cambalache, cursos, tutorías, mantenimiento de vehículos, eventos, entre otros. Los tipos de servicio los registra el usuario con rol de administrador o auxiliar (si se le concede el permiso para esto). NOTA: Es general para todos. Sirve para clasificación y estadística. Los ingresa el Usuario con Rol de Administrador | D12: Entidad | E12: PK = id_tipo_servicio
A13: 10 | B13: producto | C13: Los usuarios pueden postear productos para la venta y otros usuarios pueden comprar. El producto debe tener asociado un “Tipo de Producto”. Sigue el mismo formato de los servicios y tipos de servicio. Los ingresa el usuario participante. | D13: Entidad | E13: PK = id_producto; FK = id_usuario, id_tipo_producto
A14: 11 | B14: tipo_producto | C14: Libros, motocicleta, ropa, ticket para concierto, entre otros. Sirve para clasificación y estadística. Sirve para clasificación y estadística. Los ingresa el Usuario con Rol de Administrador. | D14: Entidad | E14: PK = id_tipo_producto
A15: 12 | B15: evento | C15: Los eventos pueden ser reuniones de estudio, talleres, actividades sociales, concursos de empleo, conferencias de los docentes, entre otros. El evento debe tener asociado un tipo de evento. El usuario que publica el evento es diferente a los usuarios que participan en el mismo. Los ingresa el usuario participante. | D15: Entidad | E15: PK = id_evento; FK = id_usuario, id_tipo_evento
A16: 13 | B16: tipo_evento | C16: Al igual que los anteriores casos de servicio y productos, se cumple lo mismo. El usuario Administrador ingresa los tipos de evento. Sirve para clasificación y estadística. Los ingresa el Usuario con Rol de Administrador | D16: Entidad | E16: PK = id_tipo_evento
A17: 14 | B17: notificacion | C17: Permite avisar a los usuarios sobre nuevas publicaciones, comentarios, eventos o servicios. | D17: Entidad | E17: PK = id_notificacion; FK = id_usuario
A18: =A17+1 -> 15 | B18: reaccion | C18: Registra interacciones rápidas como “me gusta”, “me encanta”, “me sorprende” en publicaciones o comentarios. | D18: Entidad | E18: PK = id_reaccion; FK = id_usuario, id_publicacion, id_ comentario
A19: =A18+1 -> 16 | B19: mensaje_privado | C19: Comunicación directa entre dos usuarios dentro de la red. | D19: Entidad | E19: PK = id_mensaje; FK = id_emisor, id_receptor
A20: =A19+1 -> 17 | B20: amistad | C20: Representa las conexiones entre usuarios (seguimiento o amistad). | D20: Entidad | E20: PK = id_amistad; FK = id_usuario1, id_usuario2
A21: =A20+1 -> 18 | B21: historial_actividad | C21: Guarda las acciones realizadas por cada usuario (publicar, comentar, unirse a grupo, etc.). | D21: Entidad | E21: PK = id_historial; FK = id_usuario
A22: =A21+1 -> 19 | B22: usuario_grupo | C22: Un usuario pertenece a uno o varios grupos. | D22: Relacion | E22: PK = id_usuario_grupo; FK = id_usuario, id_grupo; campos: fecha_union, rol_grupo
A23: =A22+1 -> 20 | B23: evento_usuarios | C23: Un usuario participa en eventos organizados por otros. | D23: Relacion | E23: PK = id_evento_usuario; FK = id_evento, id_usuario; campos: fecha_inscripcion, asistencia
A24: =A23+1 -> 21 | B24: usuario_reaccion | C24: Un usuario reacciona a publicaciones o comentarios. | D24: Relacion | E24: PK = id_usuario_reaccion; FK = id_usuario, id_reaccion; campos: fecha_reaccion
A25: =A24+1 -> 22 | B25: usuario_amistad | C25: Un usuario establece amistad con otro usuario. | D25: Relacion | E25: PK = id_usuario_amistad; FK = id_usuario1, id_usuario2; campos: fecha_amistad, estado
A26: =A25+1 -> 23 | B26: perfil_publicacion | C26: Un perfil contiene a una o varias publicaciones, y varios perfiles pueden contener la misma publicacion | D26: Relacion | E26: PK = id_perfil_publicacion; FK = id_perfil, id_publicacion; campos: fecha_publicacion

Sheet 1FN
A1: PRIMERA FORMA NORMAL (1FN)
A2: Pasos | B2: Descripción de las acciones para llegar a 1FN
A3: 1 | B3: Al revisar todas las tablas del modelo se evidenció que cada una cuenta con claves foráneas (FK) que permiten establecer las relaciones con otras entidades de manera precisa. Además, los atributos definidos son atómicos, es decir, no existen campos multivaluados ni repetitivos. Por esta razón, todas las tablas ya cumplen con los criterios de la Primera Forma Normal (1FN), garantizando que la información se almacene de forma ordenada, sin redundancias y con integridad referencial.
A4: 2
A5: 3
A6: 4
A7: Tablas resultantes
A9: # | B9: Tabla | G9: Versión
B10: Descripción | G10: Origen (Entidad o Relación)
A11: # | B11: Atributo | C11: Descripción Atributo | G11: Observaciones | K11: Claves
A12: 1
A13: 2
A14: 3
A15: 4
A16: 5
A18: N
A21: # | B21: Tabla | G21: Versión
B22: Descripción | G22: Origen (Entidad o Relación)
A23: # | B23: Atributo | C23: Descripción Atributo | G23: Observaciones | K23: Claves
A24: 1
A25: 2
A26: 3
A27: 4
A28: 5
A30: N
A34: Puede seguir agregando tablas. Solamente tiene que copiar y pegar hacia abajo hasta que complete todas las tablas

Sheet 2FN
A1: SEGUNDA FORMA NORMAL (2FN)
A2: Pasos | B2: Descripción de las acciones para llegar de 1FN a 2FN
A3: 1 | B3: Identificar las claves primarias compuestas y los atributos que no son clave.
A4: 2 | B4: Detectar las tependencias parciales y separar esos atributos en una nueva tabla junto con la parte de la clave de la que dependen.
A5: 3 | B5: Dejar en la tabla original únicamente los atributos que dependan de toda la clave primaria.
A6: 4 | B6: Establecer una FK en la tabla original que apunte a la nueva tabla
A7: Tablas resultantes
A9: 1 | B9: Tabla | C9: ='TABLAS '!B4 -> usuario | G9: Descripción Tabla | K9: ='TABLAS '!C4 -> Se refiere a los usuarios del sistema de información de la Red Pascualina. Un usuario debe tener asociado un tipo de usuario. NOTA IMPORTANTE: además de tener un tipo de usuario, debe tener un rol dentro de la Red.
A10: # | B10: Atributo | C10: Descripción Atributo | G10: Observaciones | K10: Claves
A11: 1 | B11: id_usuario | C11: El usuario posee un documento de identificación único que permite identificarlo de manera individual dentro del sistema. Este puede corresponder a una cédula de ciudadanía, tarjeta de identidad, pasaporte u otro documento de identificación válido. El número asociado a este documento es único para cada usuario y no puede ser compartido por otra persona. | G11: ='TABLAS '!C4 -> Se refiere a los usuarios del sistema de información de la Red Pascualina. Un usuario debe tener asociado un tipo de usuario. NOTA IMPORTANTE: además de tener un tipo de usuario, debe tener un rol dentro de la Red. | K11: PK
A12: 2 | B12: id_tipo_usuario | C12: Tipo de usuario que se le asigna a cada persona, ya sea estudiante, docente, empleado, empresario, invitado, público en general, entre otros. | K12: FK
A13: 3 | B13: id_rol | C13: Rol específico que la persona tiene definido. | K13: FK
A14: 4 | B14: correo | C14: Cada usuario cuenta con una dirección de correo electrónico única, la cual permite identificarlo dentro del sistema. | K14: UK
A15: 5 | B15: nombre1 | C15: Cada usuario posee un nombre que permite identificarlo y distinguirlo dentro de la red social.
A16: 6 | B16: nombre2 | C16: Espacio no obligatorio para segundo nombre.
A17: 7 | B17: apellido1 | C17: Espacio para primer apellido.
A18: 8 | B18: apellido2 | C18: Espacio no obligatorio para segundo apellido.
A20: 2 | B20: Tabla | C20: ='TABLAS '!B5 -> rol | G20: Descripción Tabla | K20: ='TABLAS '!C5 -> Los roles pueden ser los siguientes: administrador (adminstra la configuración de la Red en el BackOficce), auxiliar que apoya ciertas operaciones en el BacOffice, miembro (ingresa a la Red y participa en todas las actividades inherentes a este) y visitante (usuarios especiales bajo evaluación que frecuentan la Red Social. Los ingresa el usuario Administrador
A21: # | B21: Atributo | C21: Descripción Atributo | G21: Observaciones | K21: Claves
A22: 1 | B22: id_rol | C22: Rol específico que la persona tiene definido. | G22: ='TABLAS '!C5 -> Los roles pueden ser los siguientes: administrador (adminstra la configuración de la Red en el BackOficce), auxiliar que apoya ciertas operaciones en el BacOffice, miembro (ingresa a la Red y participa en todas las actividades inherentes a este) y visitante (usuarios especiales bajo evaluación que frecuentan la Red Social. Los ingresa el usuario Administrador | K22: PK
A23: 2 | B23: nombre_rol | C23: Nombre que identifica el rol dentro del sistema. | K23: UK
A25: 3 | B25: Tabla | C25: ='TABLAS '!B6 -> tipo_usuario | G25: =G20 -> Descripción Tabla | K25: ='TABLAS '!C6 -> Estos son potenciales tipos de usuario: estudiante, docente, empleado, empresario, invitado, público en general, entre otros. Sirve para clasificación y estadística. Los ingresa el Usuario con Rol de Administrador.
A26: # | B26: Atributo | C26: Descripción Atributo | G26: Observaciones | K26: Claves
A27: 1 | B27: id_tipo_usuario | C27: Código que se le asigna a cada persona, ya sea estudiante, docente, empleado, empresario, invitado, público en general, entre otros y mediante el que se le identifica. | G27: ='TABLAS '!C6 -> Estos son potenciales tipos de usuario: estudiante, docente, empleado, empresario, invitado, público en general, entre otros. Sirve para clasificación y estadística. Los ingresa el Usuario con Rol de Administrador. | K27: PK
A28: 2 | B28: nombre_tipo | C28: Nombre que identifica el tipo de usuario.
A30: 4 | B30: Tabla | C30: ='TABLAS '!B7 -> perfil | G30: Descripción Tabla | K30: ='TABLAS '!C7 -> Compartir su área de estudio, intereses, habilidades en diferentes disciplinas o deportes, etc. Estos perfiles permiten conectar con compañeros para encontrar y seguir a otros estudiantes con intereses y/o actividades similares.
A31: # | B31: Atributo | C31: Descripción Atributo | G31: Observaciones | K31: Claves
A32: 1 | B32: id_perfil | C32: Identificador del perfil. | G32: ='TABLAS '!C7 -> Compartir su área de estudio, intereses, habilidades en diferentes disciplinas o deportes, etc. Estos perfiles permiten conectar con compañeros para encontrar y seguir a otros estudiantes con intereses y/o actividades similares. | K32: PK
A33: 2 | B33: =B11 -> id_usuario | C33: Usuario al que pertenece el perfil. | K33: FK
A34: 3 | B34: descripcion | C34: Texto breve que es contenido por el perfil.
A36: 5 | B36: Tabla | C36: ='TABLAS '!B8 -> publicacion | G36: Descripción Tabla | K36: ='TABLAS '!C8 -> Compartir preguntas sobre tareas, recursos útiles, noticias de la industria tecnológica o incluso memes relevantes para la vida universitaria, entre otros. Las ingresa el usuario participante.
A37: # | B37: Atributo | C37: Descripción Atributo | G37: Observaciones | K37: Claves
A38: 1 | B38: id_publicacion | C38: Identificador de la publicación. | G38: ='TABLAS '!C7 -> Compartir su área de estudio, intereses, habilidades en diferentes disciplinas o deportes, etc. Estos perfiles permiten conectar con compañeros para encontrar y seguir a otros estudiantes con intereses y/o actividades similares. | K38: PK
A39: 2 | B39: =B11 -> id_usuario | C39: Usuario que hace la publicación. | K39: FK
A40: 3 | B40: contenido | C40: Texto de la publicación.
A41: 4 | B41: fecha | C41: Fecha de publicación.
A43: 6 | B43: Tabla | C43: ='TABLAS '!B9 -> comentario | G43: Descripción Tabla | K43: ='TABLAS '!C9 -> Comentarios que se hacen a las publicaciones. Ejemplo: un estudiante publica una nota sobre la participación de Colombia en el Mundial de Fútbol; otros usuarios pueden comentar esta publicación
A44: # | B44: Atributo | C44: Descripción Atributo | G44: Observaciones | K44: Claves
A45: 1 | B45: id_comentario | C45: Identificador del comentario. | G45: ='TABLAS '!C9 -> Comentarios que se hacen a las publicaciones. Ejemplo: un estudiante publica una nota sobre la participación de Colombia en el Mundial de Fútbol; otros usuarios pueden comentar esta publicación | K45: PK
A46: 2 | B46: id_usuario | C46: Persona que realiza el comentario. | K46: FK
...

Sheet 3FN
A1: TERCERA FORMA NORMAL (3FN)
A2: Pasos | B2: Descripción de las acciones para llegar de 2FN a 3FN
A3: 1 | B3: Tras el análisis realizado sobre las entidades y relaciones del modelo, se concluye que todas las tablas cumplen con la Tercera Forma Normal (3FN), ya que los atributos definidos son atómicos, las claves primarias garantizan la dependencia total de los campos, y las claves foráneas aseguran la correcta vinculación entre entidades sin generar redundancias ni dependencias transitivas. De esta manera, el diseño obtenido mantiene la integridad de los datos y ofrece una estructura óptima para la gestión de la información.
A4: 2
A5: 3
A6: 4
A7: Tablas resultantes
A10: 1 | B10: Tabla | C10: ='TABLAS '!B5 -> rol | G10: Descripción Tabla | K10: ='TABLAS '!C5 -> Los roles pueden ser los siguientes: administrador (adminstra la configuración de la Red en el BackOficce), auxiliar que apoya ciertas operaciones en el BacOffice, miembro (ingresa a la Red y participa en todas las actividades inherentes a este) y visitante (usuarios especiales bajo evaluación que frecuentan la Red Social. Los ingresa el usuario Administrador
A11: # | B11: Atributo | C11: Descripción Atributo | G11: Observaciones | K11: Claves
A12: 1 | B12: id_usuario | C12: El usuario posee un documento de identificación único que permite identificarlo de manera individual dentro del sistema. Este puede corresponder a una cédula de ciudadanía, tarjeta de identidad, pasaporte u otro documento de identificación válido. El número asociado a este documento es único para cada usuario y no puede ser compartido por otra persona. | G12: ='TABLAS '!C5 -> Los roles pueden ser los siguientes: administrador (adminstra la configuración de la Red en el BackOficce), auxiliar que apoya ciertas operaciones en el BacOffice, miembro (ingresa a la Red y participa en todas las actividades inherentes a este) y visitante (usuarios especiales bajo evaluación que frecuentan la Red Social. Los ingresa el usuario Administrador | K12: PK
A13: 2 | B13: id_tipo_usuario | C13: Tipo de usuario que se le asigna a cada persona, ya sea estudiante, docente, empleado, empresario, invitado, público en general, entre otros. | K13: FK
A14: 3 | B14: id_rol | C14: Rol específico que la persona tiene definido. | K14: FK
A15: 4 | B15: correo | C15: Cada usuario cuenta con una dirección de correo electrónico única, la cual permite identificarlo dentro del sistema. | K15: UK
A16: 5 | B16: nombre1 | C16: Cada usuario posee un nombre que permite identificarlo y distinguirlo dentro de la red social.
A17: 6 | B17: nombre2 | C17: Espacio no obligatorio para segundo nombre.
A18: 7 | B18: apellido1 | C18: Espacio para primer apellido.
A19: 8 | B19: apellido2 | C19: Espacio no obligatorio para segundo apellido.
A21: 2 | B21: Tabla | C21: ='TABLAS '!B6 -> tipo_usuario | G21: Descripción Tabla | K21: ='TABLAS '!C6 -> Estos son potenciales tipos de usuario: estudiante, docente, empleado, empresario, invitado, público en general, entre otros. Sirve para clasificación y estadística. Los ingresa el Usuario con Rol de Administrador.
A22: # | B22: Atributo | C22: Descripción Atributo | G22: Observaciones | K22: Claves
A23: 1 | B23: id_rol | C23: Rol específico que la persona tiene definido. | G23: ='TABLAS '!C6 -> Estos son potenciales tipos de usuario: estudiante, docente, empleado, empresario, invitado, público en general, entre otros. Sirve para clasificación y estadística. Los ingresa el Usuario con Rol de Administrador. | K23: PK
A24: 2 | B24: nombre_rol | C24: Nombre que identifica el rol dentro del sistema. | K24: UK
A26: 3 | B26: Tabla | C26: ='TABLAS '!B7 -> perfil | G26: =G21 -> Descripción Tabla | K26: ='TABLAS '!C7 -> Compartir su área de estudio, intereses, habilidades en diferentes disciplinas o deportes, etc. Estos perfiles permiten conectar con compañeros para encontrar y seguir a otros estudiantes con intereses y/o actividades similares.
A27: # | B27: Atributo | C27: Descripción Atributo | G27: Observaciones | K27: Claves
A28: 1 | B28: id_tipo_usuario | C28: Código que se le asigna a cada persona, ya sea estudiante, docente, empleado, empresario, invitado, público en general, entre otros y mediante el que se le identifica. | G28: ='TABLAS '!C7 -> Compartir su área de estudio, intereses, habilidades en diferentes disciplinas o deportes, etc. Estos perfiles permiten conectar con compañeros para encontrar y seguir a otros estudiantes con intereses y/o actividades similares. | K28: PK
A29: 2 | B29: nombre_tipo | C29: Nombre que identifica el tipo de usuario.
A31: 4 | B31: Tabla | C31: ='TABLAS '!B8 -> publicacion | G31: Descripción Tabla | K31: ='TABLAS '!C8 -> Compartir preguntas sobre tareas, recursos útiles, noticias de la industria tecnológica o incluso memes relevantes para la vida universitaria, entre otros. Las ingresa el usuario participante.
A32: # | B32: Atributo | C32: Descripción Atributo | G32: Observaciones | K32: Claves
A33: 1 | B33: id_perfil | C33: Identificador del perfil. | G33: ='TABLAS '!C8 -> Compartir preguntas sobre tareas, recursos útiles, noticias de la industria tecnológica o incluso memes relevantes para la vida universitaria, entre otros. Las ingresa el usuario participante. | K33: PK
A34: 2 | B34: =B12 -> id_usuario | C34: Usuario al que pertenece el perfil. | K34: FK
A35: 3 | B35: descripcion | C35: Texto breve que es contenido por el perfil.
A37: 5 | B37: Tabla | C37: ='TABLAS '!B9 -> comentario | G37: Descripción Tabla | K37: ='TABLAS '!C9 -> Comentarios que se hacen a las publicaciones. Ejemplo: un estudiante publica una nota sobre la participación de Colombia en el Mundial de Fútbol; otros usuarios pueden comentar esta publicación
A38: # | B38: Atributo | C38: Descripción Atributo | G38: Observaciones | K38: Claves
A39: 1 | B39: id_publicacion | C39: Identificador de la publicación. | G39: ='TABLAS '!C8 -> Compartir preguntas sobre tareas, recursos útiles, noticias de la industria tecnológica o incluso memes relevantes para la vida universitaria, entre otros. Las ingresa el usuario participante. | K39: PK
A40: 2 | B40: =B12 -> id_usuario | C40: Usuario que hace la publicación. | K40: FK
A41: 3 | B41: contenido | C41: Texto de la publicación.
A42: 4 | B42: fecha | C42: Fecha de publicación.
A44: 6 | B44: Tabla | C44: ='TABLAS '!B10 -> grupo | G44: Descripción Tabla | K44: ='TABLAS '!C10 -> Los grupos pueden ser de estudio para materias específicas, equipos para hackatones o clubes de interés (videojuegos, programación competitiva, etc.). También los empleados pueden tener sus grupos así como los docentes y los empresarios. Un grupo debe tener asociado un “Perfil”. Los ingresa el usuario participante.
A45: # | B45: Atributo | C45: Descripción Atributo | G45: Observaciones | K45: Claves
A46: 1 | B46: id_comentario | C46: Identificador del comentario. | G46: ='TABLAS '!C10 -> Los grupos pueden ser de estudio para materias específicas, equipos para hackatones o clubes de interés (videojuegos, programación competitiva, etc.). También los empleados pueden tener sus grupos así como los docentes y los empresarios. Un grupo debe tener asociado un “Perfil”. Los ingresa el usuario participante. | K46: PK
A47: 2 | B47: id_usuario | C47: Persona que realiza el comentario. | K47: FK
...

Sheet DICCIONARIO DATOS (Genérico)
A1: DICCIONARIO DE DATOS
A2: Inventario de Tablas
A3: # | B3: Tabla | F3: Descripción Tabla | X3: Observaciones
A4: 1 | B4: ='2FN'!C9 -> usuario | F4: ='2FN'!K9 -> Se refiere a los usuarios del sistema de información de la Red Pascualina. Un usuario debe tener asociado un tipo de usuario. NOTA IMPORTANTE: además de tener un tipo de usuario, debe tener un rol dentro de la Red. | X4: ='2FN'!G11 -> Se refiere a los usuarios del sistema de información de la Red Pascualina. Un usuario debe tener asociado un tipo de usuario. NOTA IMPORTANTE: además de tener un tipo de usuario, debe tener un rol dentro de la Red.
A5: =A4+1 -> 2 | B5: ='2FN'!C20 -> rol | F5: ='2FN'!K20 -> Los roles pueden ser los siguientes: administrador (adminstra la configuración de la Red en el BackOficce), auxiliar que apoya ciertas operaciones en el BacOffice, miembro (ingresa a la Red y participa en todas las actividades inherentes a este) y visitante (usuarios especiales bajo evaluación que frecuentan la Red Social. Los ingresa el usuario Administrador | X5: ='2FN'!G22 -> Los roles pueden ser los siguientes: administrador (adminstra la configuración de la Red en el BackOficce), auxiliar que apoya ciertas operaciones en el BacOffice, miembro (ingresa a la Red y participa en todas las actividades inherentes a este) y visitante (usuarios especiales bajo evaluación que frecuentan la Red Social. Los ingresa el usuario Administrador
A6: =A5+1 -> 3 | B6: ='2FN'!C25 -> tipo_usuario | F6: ='2FN'!K25 -> Estos son potenciales tipos de usuario: estudiante, docente, empleado, empresario, invitado, público en general, entre otros. Sirve para clasificación y estadística. Los ingresa el Usuario con Rol de Administrador. | X6: ='2FN'!G27 -> Estos son potenciales tipos de usuario: estudiante, docente, empleado, empresario, invitado, público en general, entre otros. Sirve para clasificación y estadística. Los ingresa el Usuario con Rol de Administrador.
A7: =A6+1 -> 4 | B7: ='2FN'!C30 -> perfil | F7: ='2FN'!K30 -> Compartir su área de estudio, intereses, habilidades en diferentes disciplinas o deportes, etc. Estos perfiles permiten conectar con compañeros para encontrar y seguir a otros estudiantes con intereses y/o actividades similares. | X7: ='2FN'!G32 -> Compartir su área de estudio, intereses, habilidades en diferentes disciplinas o deportes, etc. Estos perfiles permiten conectar con compañeros para encontrar y seguir a otros estudiantes con intereses y/o actividades similares.
A8: =A7+1 -> 5 | B8: ='2FN'!C36 -> publicacion | F8: ='2FN'!K36 -> Compartir preguntas sobre tareas, recursos útiles, noticias de la industria tecnológica o incluso memes relevantes para la vida universitaria, entre otros. Las ingresa el usuario participante. | X8: ='2FN'!G38 -> Compartir su área de estudio, intereses, habilidades en diferentes disciplinas o deportes, etc. Estos perfiles permiten conectar con compañeros para encontrar y seguir a otros estudiantes con intereses y/o actividades similares.
A9: =A8+1 -> 6 | B9: ='2FN'!C43 -> comentario | F9: ='2FN'!K43 -> Comentarios que se hacen a las publicaciones. Ejemplo: un estudiante publica una nota sobre la participación de Colombia en el Mundial de Fútbol; otros usuarios pueden comentar esta publicación | X9: ='2FN'!G45 -> Comentarios que se hacen a las publicaciones. Ejemplo: un estudiante publica una nota sobre la participación de Colombia en el Mundial de Fútbol; otros usuarios pueden comentar esta publicación
A10: =A9+1 -> 7 | B10: ='2FN'!C51 -> grupo | F10: ='2FN'!K51 -> Los grupos pueden ser de estudio para materias específicas, equipos para hackatones o clubes de interés (videojuegos, programación competitiva, etc.). También los empleados pueden tener sus grupos así como los docentes y los empresarios. Un grupo debe tener asociado un “Perfil”. Los ingresa el usuario participante. | X10: ='2FN'!G53 -> Los grupos pueden ser de estudio para materias específicas, equipos para hackatones o clubes de interés (videojuegos, programación competitiva, etc.). También los empleados pueden tener sus grupos así como los docentes y los empresarios. Un grupo debe tener asociado un “Perfil”. Los ingresa el usuario participante.
A11: =A10+1 -> 8 | B11: ='2FN'!C57 -> servicio | F11: ='2FN'!K57 -> Cambalache, cursos, tutorías, mantenimiento de vehículos, eventos, entre otros. Los tipos de servicio los registra el usuario con rol de administrador o auxiliar (si se le concede el permiso para esto). NOTA: Es general para todos. Sirve para clasificación y estadística. Los ingresa el Usuario con Rol de Administrador | X11: ='2FN'!G59 -> Los servicios los ofrece un usuario. Debe tener asociado un “Tipo de Servicio” con su descripción y precio (duración y ubicación si aplica). Los ingresa el usuario participante.
A12: =A11+1 -> 9 | B12: ='2FN'!C65 -> tipo_servicio | F12: ='2FN'!K65 -> Los servicios los ofrece un usuario. Debe tener asociado un “Tipo de Servicio” con su descripción y precio (duración y ubicación si aplica). Los ingresa el usuario participante. | X12: ='2FN'!G67 -> Cambalache, cursos, tutorías, mantenimiento de vehículos, eventos, entre otros. Los tipos de servicio los registra el usuario con rol de administrador o auxiliar (si se le concede el permiso para esto). NOTA: Es general para todos. Sirve para clasificación y estadística. Los ingresa el Usuario con Rol de Administrador
A13: =A12+1 -> 10 | B13: ='2FN'!C70 -> producto | F13: ='2FN'!K70 -> Libros, motocicleta, ropa, ticket para concierto, entre otros. Sirve para clasificación y estadística. Sirve para clasificación y estadística. Los ingresa el Usuario con Rol de Administrador. | X13: ='2FN'!G72 -> Los usuarios pueden postear productos para la venta y otros usuarios pueden comprar. El producto debe tener asociado un “Tipo de Producto”. Sigue el mismo formato de los servicios y tipos de servicio. Los ingresa el usuario participante.
A14: =A13+1 -> 11 | B14: ='2FN'!C78 -> tipo_producto | F14: ='2FN'!K78 -> Los usuarios pueden postear productos para la venta y otros usuarios pueden comprar. El producto debe tener asociado un “Tipo de Producto”. Sigue el mismo formato de los servicios y tipos de servicio. Los ingresa el usuario participante. | X14: ='2FN'!G80 -> Libros, motocicleta, ropa, ticket para concierto, entre otros. Sirve para clasificación y estadística. Sirve para clasificación y estadística. Los ingresa el Usuario con Rol de Administrador.
A15: =A14+1 -> 12 | B15: ='2FN'!C83 -> evento | F15: ='2FN'!K83 -> Al igual que los anteriores casos de servicio y productos, se cumple lo mismo. El usuario Administrador ingresa los tipos de evento. Sirve para clasificación y estadística. Los ingresa el Usuario con Rol de Administrador | X15: ='2FN'!G85 -> Los eventos pueden ser reuniones de estudio, talleres, actividades sociales, concursos de empleo, conferencias de los docentes, entre otros. El evento debe tener asociado un tipo de evento. El usuario que publica el evento es diferente a los usuarios que participan en el mismo. Los ingresa el usuario participante.
A16: =A15+1 -> 13 | B16: ='2FN'!C91 -> tipo_evento | F16: ='2FN'!K91 -> Los eventos pueden ser reuniones de estudio, talleres, actividades sociales, concursos de empleo, conferencias de los docentes, entre otros. El evento debe tener asociado un tipo de evento. El usuario que publica el evento es diferente a los usuarios que participan en el mismo. Los ingresa el usuario participante. | X16: ='2FN'!G93 -> Al igual que los anteriores casos de servicio y productos, se cumple lo mismo. El usuario Administrador ingresa los tipos de evento. Sirve para clasificación y estadística. Los ingresa el Usuario con Rol de Administrador
A17: =A16+1 -> 14 | B17: ='2FN'!C96 -> notificacion | F17: ='2FN'!K96 -> Permite avisar a los usuarios sobre nuevas publicaciones, comentarios, eventos o servicios. | X17: ='2FN'!G98 -> Permite avisar a los usuarios sobre nuevas publicaciones, comentarios, eventos o servicios.
A18: =A17+1 -> 15 | B18: ='2FN'!C103 -> reaccion | F18: ='2FN'!K96 -> Permite avisar a los usuarios sobre nuevas publicaciones, comentarios, eventos o servicios. | X18: ='2FN'!G98 -> Permite avisar a los usuarios sobre nuevas publicaciones, comentarios, eventos o servicios.
A19: =A18+1 -> 16 | B19: ='2FN'!C111 -> mensaje_privado | F19: ='2FN'!K111 -> Comunicación directa entre dos usuarios dentro de la red. | X19: ='2FN'!G113 -> Comunicación directa entre dos usuarios dentro de la red.
A20: =A19+1 -> 17 | B20: ='2FN'!C119 -> amistad | F20: ='2FN'!K119 -> Representa las conexiones entre usuarios (seguimiento o amistad). | X20: ='2FN'!G121 -> Representa las conexiones entre usuarios (seguimiento o amistad).
A21: =A20+1 -> 18 | B21: ='2FN'!C126 -> historial_actividad | F21: ='2FN'!K126 -> Guarda las acciones realizadas por cada usuario (publicar, comentar, unirse a grupo, etc.). | X21: ='2FN'!G128 -> Guarda las acciones realizadas por cada usuario (publicar, comentar, unirse a grupo, etc.).
A22: =A21+1 -> 19 | B22: ='2FN'!C133 -> usuario_grupo | F22: ='2FN'!K133 -> Un usuario pertenece a uno o varios grupos. | X22: ='2FN'!G135 -> Un usuario pertenece a uno o varios grupos.
A23: =A22+1 -> 20 | B23: ='2FN'!C141 -> evento_usuarios | F23: ='2FN'!K141 -> Un usuario participa en eventos organizados por otros. | X23: ='2FN'!G143 -> Un usuario participa en eventos organizados por otros.
A24: =A23+1 -> 21 | B24: ='2FN'!C150 -> usuario_reaccion | F24: ='2FN'!K150 -> Un usuario reacciona a publicaciones o comentarios. | X24: ='2FN'!G152 -> Un usuario reacciona a publicaciones o comentarios.
A25: =A24+1 -> 22 | B25: ='2FN'!C157 -> usuario_amistad | F25: ='2FN'!K157 -> Un usuario establece amistad con otro usuario. | X25: ='2FN'!G159 -> Un usuario establece amistad con otro usuario.
A26: =A25+1 -> 23 | B26: ='2FN'!C165 -> perfil_publicacion | F26: ='2FN'!K165 -> Un perfil contiene a una o varias publicaciones, y varios perfiles pueden contener la misma publicacion | X26: ='2FN'!G167 -> Un perfil contiene a una o varias publicaciones, y varios perfiles pueden contener la misma publicacion
A28: Tablas en Detalle
A30: 1 | B30: Tabla | C30: =B4 -> usuario | G30: Descripción Tabla | K30: =F4 -> Se refiere a los usuarios del sistema de información de la Red Pascualina. Un usuario debe tener asociado un tipo de usuario. NOTA IMPORTANTE: además de tener un tipo de usuario, debe tener un rol dentro de la Red. | X30: Versión | Y30: 1
A31: # | B31: Campo | C31: Descripción Campo | G31: Tipo Dato (Genérico) | K31: Tamaño / Longitud | O31: Nulo | R31: PK | T31: FK | V31: UK | X31: Nota/Comentarios
A32: 1 | B32: id_usuario | C32: El usuario posee un documento de identificación único que permite identificarlo de manera individual dentro del sistema. Este puede corresponder a una cédula de ciudadanía, tarjeta de identidad, pasaporte u otro documento de identificación válido. El número asociado a este documento es único para cada usuario y no puede ser compartido por otra persona. | G32: AUTOINCREMENTABLE | R32: s
A33: 2 | B33: id_tipo_usuario | C33: Tipo de usuario que se le asigna a cada persona, ya sea estudiante, docente, empleado, empresario, invitado, público en general, entre otros. | G33: ENTERO | T33: s
A34: 3 | B34: id_rol | C34: Rol específico que la persona tiene definido. | G34: ENTERO | T34: s
A35: 4 | B35: correo | C35: Cada usuario cuenta con una dirección de correo electrónico única, la cual permite identificarlo dentro del sistema. | G35: ENTERO | V35: s
A36: 5 | B36: nombre1 | C36: Cada usuario posee un nombre que permite identificarlo y distinguirlo dentro de la red social. | G36: TEXTO_CORTO | O36: No
A37: 6 | B37: nombre2 | C37: Espacio no obligatorio para segundo nombre. | G37: TEXTO_CORTO | O37: No
A38: 7 | B38: apellido1 | C38: Espacio para primer apellido. | G38: TEXTO_CORTO | O38: No
A39: 8 | B39: apellido2 | C39: Espacio no obligatorio para segundo apellido. | G39: TEXTO_CORTO | O39: No
A40: NOTA: En las columnas PK, FK y UK debe colocar “S” solamente cuando aplique. En la columna “Nulo” coloque “No” en caso de que el campo debe estar valorizado
A42: 2 | B42: Tabla | C42: =B5 -> rol | G42: Descripción Tabla | K42: =F5 -> Los roles pueden ser los siguientes: administrador (adminstra la configuración de la Red en el BackOficce), auxiliar que apoya ciertas operaciones en el BacOffice, miembro (ingresa a la Red y participa en todas las actividades inherentes a este) y visitante (usuarios especiales bajo evaluación que frecuentan la Red Social. Los ingresa el usuario Administrador | X42: Versión | Y42: 1
A43: # | B43: Campo | C43: Descripción Campo | G43: Tipo Dato (Genérico) | K43: Tamaño / Longitud | O43: Nulo | R43: PK | T43: FK | V43: UK | X43: Nota/Comentarios
...
